<?xml version="1.0" ?>
<sdf version="1.6">
	<model name="robot">
		<link name="arm_base">
			<pose>0 0 0 0 0 0</pose>
			<inertial>
				<inertia>
					<ixx>0.00820312</ixx>
					<iyy>0.00820312</iyy>
					<izz>0.00703125</izz>
				</inertia>
				<mass>10.00000000</mass>
			</inertial>
			<visual name="arm_base_vis">
				<geometry>
					<cylinder>
						<radius>0.0375</radius>
						<length>0.075</length>
					</cylinder>
				</geometry>
			</visual>
			<collision name="arm_base_col">
				<geometry>
					<cylinder>
						<radius>0.0375</radius>
						<length>0.075</length>
					</cylinder>
				</geometry>
			</collision>
		</link>
		<link name="arm_base_top">
			<pose>0 0 0.0525 0 0 0</pose>
			<inertial>
				<inertia>
					<ixx>0.00005000</ixx>
					<iyy>0.00005000</iyy>
					<izz>0.00002500</izz>
				</inertia>
				<mass>0.50000000</mass>
			</inertial>
			<visual name="arm_base_top_vis">
				<geometry>
					<cylinder>
						<radius>0.01</radius>
						<length>0.03</length>
					</cylinder>
				</geometry>
			</visual>
			<collision name="arm_base_top_col">
				<geometry>
					<cylinder>
						<radius>0.01</radius>
						<length>0.03</length>
					</cylinder>
				</geometry>
			</collision>
		</link>
		 <joint name="fixed" type="fixed">
			<child>arm_base</child>
			<parent>world</parent>
		</joint>
		<joint name="armBase_armBaseTop" type="fixed">
			<child>arm_base_top</child>
			<parent>arm_base</parent>
		</joint>

		<link name="arm1">
			<pose>0 0 0.14250000000000002 0 0 0</pose>
			<inertial>
				<inertia>
					<ixx>0.00190000</ixx>
					<iyy>0.00190000</iyy>
					<izz>0.00005000</izz>
				</inertia>
				<mass>1.00000000</mass>
			</inertial>
			<visual name="arm1_vis">
				<geometry>
					<cylinder>
						<radius>0.01</radius>
						<length>0.15</length>
					</cylinder>
				</geometry>
			</visual>
			<collision name="arm1_col">
				<geometry>
					<cylinder>
						<radius>0.01</radius>
						<length>0.15</length>
					</cylinder>
				</geometry>
			</collision>
		</link>
		<joint name="armBaseTop_arm1" type="fixed">
			<child>arm1</child>
			<parent>arm_base_top</parent>
		</joint>
		<link name="arm2">
			<pose>0 0 0.29250000000000004 0 0 0</pose>
			<inertial>
				<inertia>
					<ixx>0.00190000</ixx>
					<iyy>0.00190000</iyy>
					<izz>0.00005000</izz>
				</inertia>
				<mass>1.00000000</mass>
			</inertial>
			<visual name="arm2_vis">
				<geometry>
					<cylinder>
						<radius>0.01</radius>
						<length>0.15</length>
					</cylinder>
				</geometry>
			</visual>
			<collision name="arm2_col">
				<geometry>
					<cylinder>
						<radius>0.01</radius>
						<length>0.15</length>
					</cylinder>
				</geometry>
			</collision>
		</link>
		<joint name="arm1_arm2" type="fixed">
			<child>arm2</child>
			<parent>arm1</parent>
		</joint>
		<link name="palm">
			<pose>0 0 0.37500000000000006 0 0 0</pose>
			<inertial>
				<inertia>
					<ixx>0.00002500</ixx>
					<iyy>0.00002500</iyy>
					<izz>0.00003750</izz>
				</inertia>
				<mass>0.33333333</mass>
			</inertial>
			<visual name="palm_vis">
				<geometry>
					<cylinder>
						<radius>0.015</radius>
						<length>0.015</length>
					</cylinder>
				</geometry>
			</visual>
			<collision name="palm_col">
				<geometry>
					<cylinder>
						<radius>0.015</radius>
						<length>0.015</length>
					</cylinder>
				</geometry>
			</collision>
		</link>
		<joint name="palm_joint" type="fixed">
			<child>palm</child>
			<parent>arm2</parent>
		</joint>

		<link name="finger_one">
			<pose>0 0.0075 0.4075000000000001 0 0 0</pose>
			<inertial>
				<inertia>
					<ixx>0.00005296</ixx>
					<iyy>0.00005296</iyy>
					<izz>0.00000176</izz>
				</inertia>
				<mass>0.25000000</mass>
			</inertial>
			<visual name="finger_one_vis">
				<geometry>
					<cylinder>
						<radius>0.00375</radius>
						<length>0.049999999999999996</length>
					</cylinder>
				</geometry>
			</visual>
			<collision name="finger_one_col">
				<geometry>
					<cylinder>
						<radius>0.00375</radius>
						<length>0.049999999999999996</length>
					</cylinder>
				</geometry>
			</collision>
		</link>
		<joint name="finger_one_joint" type="revolute">
			<pose>0 0 -0.024999999999999998 0 0 0</pose>
			<child>finger_one</child>
			<parent>palm</parent>
			<axis>
				<xyz>1 0 0</xyz>
				<dynamics>
					<friction>0.05</friction>
					<damping>0.03</damping>
				</dynamics>
				<limit>
					<upper>0</upper>
					<lower>0.7853981633974483</lower>
				</limit>
			</axis>
		</joint>
		<link name="finger_two">
			<pose>0 -0.0075 0.4075000000000001 0 0 0</pose>
			<inertial>
				<inertia>
					<ixx>0.00005296</ixx>
					<iyy>0.00005296</iyy>
					<izz>0.00000176</izz>
				</inertia>
				<mass>0.25000000</mass>
			</inertial>
			<visual name="finger_two_vis">
				<geometry>
					<cylinder>
						<radius>0.00375</radius>
						<length>0.049999999999999996</length>
					</cylinder>
				</geometry>
			</visual>
			<collision name="finger_two_col">
				<geometry>
					<cylinder>
						<radius>0.00375</radius>
						<length>0.049999999999999996</length>
					</cylinder>
				</geometry>
			</collision>
		</link>
		<joint name="finger_two_joint" type="revolute">
			<pose>0 0 -0.024999999999999998 0 0 0</pose>
			<child>finger_two</child>
			<parent>palm</parent>
			<axis>
				<xyz>1 0 0</xyz>
				<dynamics>
					<friction>0.05</friction>
					<damping>0.03</damping>
				</dynamics>
				<limit>
					<upper>-0.7853981633974483</upper>
					<lower>0</lower>
				</limit>
			</axis>
		</joint>
		<link name="finger_three">
			<pose>0.0075 0 0.4075000000000001 0 0 0</pose>
			<inertial>
				<inertia>
					<ixx>0.00005296</ixx>
					<iyy>0.00005296</iyy>
					<izz>0.00000176</izz>
				</inertia>
				<mass>0.25000000</mass>
			</inertial>
			<visual name="finger_three_vis">
				<geometry>
					<cylinder>
						<radius>0.00375</radius>
						<length>0.049999999999999996</length>
					</cylinder>
				</geometry>
			</visual>
			<collision name="finger_three_col">
				<geometry>
					<cylinder>
						<radius>0.00375</radius>
						<length>0.049999999999999996</length>
					</cylinder>
				</geometry>
			</collision>
		</link>
		<joint name="finger_three_joint" type="revolute">
			<pose>0 0 -0.024999999999999998 0 0 0</pose>
			<child>finger_three</child>
			<parent>palm</parent>
			<axis>
				<xyz>0 1 0</xyz>
				<dynamics>
					<friction>0.05</friction>
					<damping>0.03</damping>
				</dynamics>
				<limit>
					<upper>0.7853981633974483</upper>
					<lower>0</lower>
				</limit>
			</axis>
		</joint>
		<link name="finger_four">
			<pose>-0.0075 0 0.4075000000000001 0 0 0</pose>
			<inertial>
				<inertia>
					<ixx>0.00005296</ixx>
					<iyy>0.00005296</iyy>
					<izz>0.00000176</izz>
				</inertia>
				<mass>0.25000000</mass>
			</inertial>
			<visual name="finger_four_vis">
				<geometry>
					<cylinder>
						<radius>0.00375</radius>
						<length>0.049999999999999996</length>
					</cylinder>
				</geometry>
			</visual>
			<collision name="finger_four_col">
				<geometry>
					<cylinder>
						<radius>0.00375</radius>
						<length>0.049999999999999996</length>
					</cylinder>
				</geometry>
			</collision>
		</link>
		<joint name="finger_four_joint" type="revolute">
			<pose>0 0 -0.024999999999999998 0 0 0</pose>
			<child>finger_four</child>
			<parent>palm</parent>
			<axis>
				<xyz>0 1 0</xyz>
				<dynamics>
					<friction>0.05</friction>
					<damping>0.03</damping>
				</dynamics>
				<limit>
					<upper>0</upper>
					<lower>-0.7853981633974483</lower>
				</limit>
			</axis>
		</joint>
		<link name="finger_one_tip">
			<pose>0 0.0075 0.4575000000000001 0 0 0</pose>
			<inertial>
				<inertia>
					<ixx>0.00005296</ixx>
					<iyy>0.00005296</iyy>
					<izz>0.00000176</izz>
				</inertia>
				<mass>0.25000000</mass>
			</inertial>
			<visual name="finger_one_tip_vis">
				<geometry>
					<cylinder>
						<radius>0.00375</radius>
						<length>0.049999999999999996</length>
					</cylinder>
				</geometry>
			</visual>
			<collision name="finger_one_tip_col">
				<geometry>
					<cylinder>
						<radius>0.00375</radius>
						<length>0.049999999999999996</length>
					</cylinder>
				</geometry>
			</collision>
			<sensor name="finger_one_tip_sensor" type="contact">
				<contact>
					<collision>finger_one_tip_col</collision>
				</contact>
				<always_on>1</always_on>
				<update_rate>30</update_rate>
				<visualize>true</visualize>
				<plugin filename="libcontact_plugin.so" name="my_plugin"/>
			</sensor>
		</link>
		<joint name="finger_one_tip_joint" type="revolute">
			<pose>0 0 -0.024999999999999998 0 0 0</pose>
			<child>finger_one_tip</child>
			<parent>finger_one</parent>
			<axis>
				<xyz>1 0 0</xyz>
				<dynamics>
					<friction>0.05</friction>
					<damping>0.03</damping>
				</dynamics>
				<limit>
					<upper>-1.5707963267948966</upper>
					<lower>0</lower>
				</limit>
			</axis>
		</joint>
		<link name="finger_two_tip">
			<pose>0 -0.0075 0.4575000000000001 0 0 0</pose>
			<inertial>
				<inertia>
					<ixx>0.00005296</ixx>
					<iyy>0.00005296</iyy>
					<izz>0.00000176</izz>
				</inertia>
				<mass>0.25000000</mass>
			</inertial>
			<visual name="finger_two_tip_vis">
				<geometry>
					<cylinder>
						<radius>0.00375</radius>
						<length>0.049999999999999996</length>
					</cylinder>
				</geometry>
			</visual>
			<collision name="finger_two_tip_col">
				<geometry>
					<cylinder>
						<radius>0.00375</radius>
						<length>0.049999999999999996</length>
					</cylinder>
				</geometry>
			</collision>
			<sensor name="finger_two_tip_sensor" type="contact">
				<contact>
					<collision>finger_two_tip_col</collision>
				</contact>
				<always_on>1</always_on>
				<update_rate>30</update_rate>
				<visualize>true</visualize>
				<plugin filename="libcontact_plugin.so" name="my_plugin"/>
			</sensor>
		</link>
		<joint name="finger_two_tip_joint" type="revolute">
			<pose>0 0 -0.024999999999999998 0 0 0</pose>
			<child>finger_two_tip</child>
			<parent>finger_two</parent>
			<axis>
				<xyz>1 0 0</xyz>
				<dynamics>
					<friction>0.05</friction>
					<damping>0.03</damping>
				</dynamics>
				<limit>
					<upper>0</upper>
					<lower>1.5707963267948966</lower>
				</limit>
			</axis>
		</joint>
		<link name="finger_three_tip">
			<pose>0.0075 0 0.4575000000000001 0 0 0</pose>
			<inertial>
				<inertia>
					<ixx>0.00005296</ixx>
					<iyy>0.00005296</iyy>
					<izz>0.00000176</izz>
				</inertia>
				<mass>0.25000000</mass>
			</inertial>
			<visual name="finger_three_tip_vis">
				<geometry>
					<cylinder>
						<radius>0.00375</radius>
						<length>0.049999999999999996</length>
					</cylinder>
				</geometry>
			</visual>
			<collision name="finger_three_tip_col">
				<geometry>
					<cylinder>
						<radius>0.00375</radius>
						<length>0.049999999999999996</length>
					</cylinder>
				</geometry>
			</collision>
			<sensor name="finger_three_tip_sensor" type="contact">
				<contact>
					<collision>finger_three_tip_col</collision>
				</contact>
				<always_on>1</always_on>
				<update_rate>30</update_rate>
				<visualize>true</visualize>
				<plugin filename="libcontact_plugin.so" name="my_plugin"/>
			</sensor>
		</link>
		<joint name="finger_three_tip_joint" type="revolute">
			<pose>0 0 -0.024999999999999998 0 0 0</pose>
			<child>finger_three_tip</child>
			<parent>finger_three</parent>
			<axis>
				<xyz>0 1 0</xyz>
				<dynamics>
					<friction>0.05</friction>
					<damping>0.03</damping>
				</dynamics>
				<limit>
					<upper>0</upper>
					<lower>-1.5707963267948966</lower>
				</limit>
			</axis>
		</joint>
		<link name="finger_four_tip">
			<pose>-0.0075 0 0.4575000000000001 0 0 0</pose>
			<inertial>
				<inertia>
					<ixx>0.00005296</ixx>
					<iyy>0.00005296</iyy>
					<izz>0.00000176</izz>
				</inertia>
				<mass>0.25000000</mass>
			</inertial>
			<visual name="finger_four_tip_vis">
				<geometry>
					<cylinder>
						<radius>0.00375</radius>
						<length>0.049999999999999996</length>
					</cylinder>
				</geometry>
			</visual>
			<collision name="finger_four_tip_col">
				<geometry>
					<cylinder>
						<radius>0.00375</radius>
						<length>0.049999999999999996</length>
					</cylinder>
				</geometry>
			</collision>
			<sensor name="finger_four_tip_sensor" type="contact">
				<contact>
					<collision>finger_four_tip_col</collision>
				</contact>
				<always_on>1</always_on>
				<update_rate>30</update_rate>
				<visualize>true</visualize>
				<plugin filename="libcontact_plugin.so" name="my_plugin"/>
			</sensor>
		</link>
		<joint name="finger_four_tip_joint" type="revolute">
			<pose>0 0 -0.024999999999999998 0 0 0</pose>
			<child>finger_four_tip</child>
			<parent>finger_four</parent>
			<axis>
				<xyz>0 1 0</xyz>
				<dynamics>
					<friction>0.05</friction>
					<damping>0.03</damping>
				</dynamics>
				<limit>
					<upper>1.5707963267948966</upper>
					<lower>0</lower>
				</limit>
			</axis>
		</joint>
		<plugin filename="libgripper_plugin.so" name="gripper_plugin"/>
		<plugin filename="libarm_controller.so" name="arm_controller"/>
	</model>
</sdf>
